 * Running on http://10.21.62.92:8080/ (Press CTRL+C to quit)
 * Restarting with stat
 * Debugger is active!
 * Debugger PIN: 277-558-600
T
Exception in thread Thread-1 (most likely raised during interpreter shutdown):
Traceback (most recent call last):
  File "/usr/lib/python2.7/threading.py", line 810, in __bootstrap_inner
  File "/usr/lib/python2.7/threading.py", line 763, in run
  File "/usr/local/lib/python2.7/dist-packages/werkzeug/serving.py", line 702, in inner
  File "/usr/local/lib/python2.7/dist-packages/werkzeug/serving.py", line 539, in serve_forever
  File "/usr/lib/python2.7/SocketServer.py", line 241, in serve_forever
  File "/usr/lib/python2.7/threading.py", line 585, in set
  File "/usr/lib/python2.7/threading.py", line 406, in notifyAll
<type 'exceptions.TypeError'>: 'NoneType' object is not callable
T
